Workbook

Sheet gift_detail
A1: gift_id | B1: gitf_name | C1: target_gender | D1: shop_name | E1: price | F1: shop_link | G1: pic_link
A2: =INT((ROW()-2)/3)+1 -> 1 | B2: {=XLOOKUP(A2, manage_gift!A:A, manage_gift!B:B)} -> Wireless Earbuds | C2: {=XLOOKUP(A2, manage_gift!A:A, manage_gift!E:E)} -> 3 | D2: Shopee | E2: 389 | F2: https://shopee.co.th/Lenovo-LP40-Pro-LP40-Plus-%E0%B8%AB%E0%B8%B9%E0%B8%9F%E0%B8%B1%E0%B8%87%E0%B8%AD%E0%B8%B4%E0%B8%99%E0%B9%80%E0%B8%AD%E0%B8%B5%E0%B8%A2%E0%B8%A3%E0%B9%8C%E0%B9%84%E0%B8%A3%E0%B9%89%E0%B8%AA%E0%B8%B2%E0%B8%A2%E0%B8%9A%E0%B8%A5%E0%B8%B9%E0%B8%97%E0%B8%B9%E0%B8%98-HD-%E0%B8%AA%E0%B9%80%E0%B8%95%E0%B8%AD%E0%B8%A3%E0%B8%B4%E0%B9%82%E0%B8%AD%E0%B8%A5%E0%B8%94%E0%B9%80%E0%B8%AA%E0%B8%B5%E0%B8%A2%E0%B8%87%E0%B8%A3%E0%B8%9A%E0%B8%81%E0%B8%A7%E0%B8%99-i.987690207.27783667072?extraParams=%7B%22display_model_id%22%3A258199125008%2C%22model_selection_logic%22%3A3%7D&sp_atk=92345afc-507a-4275-81c1-6165d77d4cbe&xptdk=92345afc-507a-4275-81c1-6165d77d4cbe | G2: https://down-th.img.susercontent.com/file/vn-11134207-7qukw-lhifeeqaf0cl82.webp
A3: =INT((ROW()-2)/3)+1 -> 1 | B3: {=XLOOKUP(A3, manage_gift!A:A, manage_gift!B:B)} -> Wireless Earbuds | C3: {=XLOOKUP(A3, manage_gift!A:A, manage_gift!E:E)} -> 3 | D3: Shopee | E3: 199 | F3: https://shopee.co.th/Lenovo-LP25-%E0%B9%84%E0%B8%A3%E0%B9%89%E0%B8%AA%E0%B8%B2%E0%B8%A2%E0%B8%9A%E0%B8%A5%E0%B8%B9%E0%B8%97%E0%B8%B9%E0%B8%98-5.3-TWS-%E0%B8%AB%E0%B8%B9%E0%B8%9F%E0%B8%B1%E0%B8%87%E0%B8%AD%E0%B8%B4%E0%B8%99%E0%B9%80%E0%B8%AD%E0%B8%B5%E0%B8%A2%E0%B8%A3%E0%B9%8C%E0%B9%81%E0%B8%9A%E0%B8%9A%E0%B8%9E%E0%B8%81%E0%B8%9E%E0%B8%B2%E0%B8%9E%E0%B8%A3%E0%B9%89%E0%B8%AD%E0%B8%A1%E0%B9%84%E0%B8%A1%E0%B9%82%E0%B8%84%E0%B8%A3%E0%B9%82%E0%B8%9F%E0%B8%99-i.988814143.40323208744?extraParams=%7B%22display_model_id%22%3A49600706783%2C%22model_selection_logic%22%3A3%7D&sp_atk=277fd512-bb8c-4f54-a8da-a3b16db37a93&xptdk=277fd512-bb8c-4f54-a8da-a3b16db37a93 | G3: https://down-th.img.susercontent.com/file/cn-11134207-820l4-mjgox1g3u9s346.webp
A4: =INT((ROW()-2)/3)+1 -> 1 | B4: {=XLOOKUP(A4, manage_gift!A:A, manage_gift!B:B)} -> Wireless Earbuds | C4: {=XLOOKUP(A4, manage_gift!A:A, manage_gift!E:E)} -> 3 | D4: Shopee | E4: 99 | F4: https://shopee.co.th/Hoco-EW26-True-wireless-stereo-headset-%E0%B8%AB%E0%B8%B9%E0%B8%9F%E0%B8%B1%E0%B8%87%E2%80%8B%E0%B8%9A%E0%B8%A5%E0%B8%B9%E0%B8%97%E0%B8%B9%E0%B8%98%E2%80%8B%E0%B9%84%E0%B8%A3%E0%B9%89%E0%B8%AA%E0%B8%B2%E0%B8%A2%E2%80%8B%E0%B8%A3%E0%B8%B8%E0%B9%88%E0%B8%99%E0%B9%83%E0%B8%AB%E0%B8%A1%E0%B9%88%E2%80%8B%E0%B8%A5%E0%B9%88%E0%B8%B2-i.374944741.19141495576?extraParams=%7B%22display_model_id%22%3A212106828183%2C%22model_selection_logic%22%3A3%7D&sp_atk=4daa172a-8e8a-4a11-9af7-5bd6db7eb6a6&xptdk=4daa172a-8e8a-4a11-9af7-5bd6db7eb6a6 | G4: https://down-th.img.susercontent.com/file/th-11134207-81ztd-mhzuuzd046x216.webp
A5: =INT((ROW()-2)/3)+1 -> 2 | B5: {=XLOOKUP(A5, manage_gift!A:A, manage_gift!B:B)} -> Smart Watch | C5: {=XLOOKUP(A5, manage_gift!A:A, manage_gift!E:E)} -> 3 | D5: Shopee | E5: 970 | F5: https://shopee.co.th/XIAOMI-Smart-Watch-%E0%B8%A3%E0%B8%A7%E0%B8%A1%E0%B8%99%E0%B8%B2%E0%B8%AC%E0%B8%B4%E0%B8%81%E0%B8%B2-%E0%B8%AA%E0%B8%A1%E0%B8%B2%E0%B8%A3%E0%B9%8C%E0%B8%97%E0%B8%A7%E0%B8%AD%E0%B8%97%E0%B8%8A%E0%B9%8C-%E0%B8%95%E0%B8%A3%E0%B8%A7%E0%B8%88%E0%B8%A7%E0%B8%B1%E0%B8%94%E0%B8%AA%E0%B8%B8%E0%B8%82%E0%B8%A0%E0%B8%B2%E0%B8%9E-%E0%B8%AD%E0%B8%AD%E0%B8%81%E0%B8%81%E0%B8%B3%E0%B8%A5%E0%B8%B1%E0%B8%87%E0%B8%81%E0%B8%B2%E0%B8%A2-i.1320287136.50654655869?extraParams=%7B%22display_model_id%22%3A292333234368%2C%22model_selection_logic%22%3A3%7D&sp_atk=a45c2f72-65c4-4e21-b7b7-50dab063bfcb&xptdk=a45c2f72-65c4-4e21-b7b7-50dab063bfcb | G5: https://down-th.img.susercontent.com/file/sg-11134201-8260g-mjgoq9taqscn2f.webp
A6: =INT((ROW()-2)/3)+1 -> 2 | B6: {=XLOOKUP(A6, manage_gift!A:A, manage_gift!B:B)} -> Smart Watch | C6: {=XLOOKUP(A6, manage_gift!A:A, manage_gift!E:E)} -> 3 | D6: Shopee | E6: 158 | F6: https://shopee.co.th/%E0%B8%99%E0%B8%B2%E0%B8%AC%E0%B8%B4%E0%B8%81%E0%B8%B2%E0%B8%82%E0%B9%89%E0%B8%AD%E0%B8%A1%E0%B8%B7%E0%B8%AD%E0%B8%AA%E0%B8%A1%E0%B8%B2%E0%B8%A3%E0%B9%8C%E0%B8%97%E0%B8%A7%E0%B8%AD%E0%B8%97%E0%B8%8A%E0%B9%8C-H9-%E0%B8%AB%E0%B8%99%E0%B9%89%E0%B8%B2%E0%B8%88%E0%B8%AD%E0%B8%AA%E0%B8%B1%E0%B8%A1%E0%B8%9C%E0%B8%B1%E0%B8%AA-%E0%B8%A3%E0%B8%B1%E0%B8%9A%E0%B8%AA%E0%B8%B2%E0%B8%A2-%E0%B8%84%E0%B8%B8%E0%B8%A2-%E0%B8%A7%E0%B8%B1%E0%B8%94%E0%B8%AD%E0%B8%B1%E0%B8%95%E0%B8%A3%E0%B8%B2%E0%B8%81%E0%B8%B2%E0%B8%A3%E0%B9%80%E0%B8%95%E0%B9%89%E0%B8%99%E0%B8%82%E0%B8%AD%E0%B8%87%E0%B8%AB%E0%B8%B1%E0%B8%A7%E0%B9%83%E0%B8%88-%E0%B8%84%E0%B8%A7%E0%B8%B2%E0%B8%A1%E0%B8%94%E0%B8%B1%E0%B8%99%E0%B9%82%E0%B8%A5%E0%B8%AB%E0%B8%B4%E0%B8%95-%E0%B8%AA%E0%B9%8D%E0%B8%B2%E0%B8%AB%E0%B8%A3%E0%B8%B1%E0%B8%9A-Android-IOS-i.1629715210.44475153667?extraParams=%7B%22display_model_id%22%3A244049420310%2C%22model_selection_logic%22%3A3%7D&rModelId=244049420310&sp_atk=01c10efd-7691-4649-809a-b585dae6bca2&vItemId=43613512004&vModelId=206209679098&vShopId=1449018616&xptdk=01c10efd-7691-4649-809a-b585dae6bca2 | G6: https://down-th.img.susercontent.com/file/sg-11134201-7rff6-m9x97p5cl1ll0e.webp
A7: =INT((ROW()-2)/3)+1 -> 2 | B7: {=XLOOKUP(A7, manage_gift!A:A, manage_gift!B:B)} -> Smart Watch | C7: {=XLOOKUP(A7, manage_gift!A:A, manage_gift!E:E)} -> 3 | D7: Shopee | E7: 1490 | F7: https://shopee.co.th/Samsung-Smart-Watch-Galaxy-Fit3-%E0%B8%88%E0%B8%AD%E0%B8%82%E0%B8%99%E0%B8%B2%E0%B8%94-1.6--i.30330278.28800415424?extraParams=%7B%22display_model_id%22%3A236351295000%2C%22model_selection_logic%22%3A3%7D&sp_atk=0a6ddf64-9f9f-4544-a281-eb3eda090e4c&xptdk=0a6ddf64-9f9f-4544-a281-eb3eda090e4c | G7: https://down-th.img.susercontent.com/file/th-11134207-7r98r-lvig3cgas1iy5d.webp
A8: =INT((ROW()-2)/3)+1 -> 3 | B8: {=XLOOKUP(A8, manage_gift!A:A, manage_gift!B:B)} -> Gaming Mouse | C8: {=XLOOKUP(A8, manage_gift!A:A, manage_gift!E:E)} -> 1 | D8: Shopee | E8: 69 | F8: https://shopee.co.th/%E0%B9%83%E0%B8%AB%E0%B8%A1%E0%B9%88-%E0%B9%80%E0%B8%A1%E0%B8%B2%E0%B8%AA%E0%B9%8C%E0%B9%84%E0%B8%A3%E0%B9%89%E0%B8%AA%E0%B8%B2%E0%B8%A2%E0%B8%84%E0%B8%B8%E0%B8%93%E0%B8%A0%E0%B8%B2%E0%B8%9E%E0%B8%94%E0%B8%B5-%E0%B9%80%E0%B8%81%E0%B8%A1%E0%B8%A1%E0%B8%B4%E0%B9%88%E0%B8%87-%E0%B8%A3%E0%B8%B9%E0%B8%9B%E0%B9%80%E0%B8%82%E0%B9%89%E0%B8%B2%E0%B8%A1%E0%B8%B7%E0%B8%AD%E0%B8%87%E0%B9%88%E0%B8%B2%E0%B8%A2-%E0%B9%83%E0%B8%8A%E0%B9%89%E0%B8%87%E0%B8%B2%E0%B8%99%E0%B9%84%E0%B8%94%E0%B9%89%E0%B8%99%E0%B8%B2%E0%B8%99-%E0%B8%A1%E0%B8%B5%E0%B8%84%E0%B8%A7%E0%B8%B2%E0%B8%A1%E0%B9%81%E0%B8%A1%E0%B9%88%E0%B8%99%E0%B8%A2%E0%B8%B3%E0%B8%AA%E0%B8%B9%E0%B8%87005-i.261096614.7038411734?extraParams=%7B%22display_model_id%22%3A50014448143%2C%22model_selection_logic%22%3A3%7D&sp_atk=a3f2006e-00c7-4e68-9c50-ffa97a7710b5&xptdk=a3f2006e-00c7-4e68-9c50-ffa97a7710b5 | G8: https://down-th.img.susercontent.com/file/89a2fdaf0f485ed04683e3cf2e4d5652@resize_w900_nl.webp
A9: =INT((ROW()-2)/3)+1 -> 3 | B9: {=XLOOKUP(A9, manage_gift!A:A, manage_gift!B:B)} -> Gaming Mouse | C9: {=XLOOKUP(A9, manage_gift!A:A, manage_gift!E:E)} -> 1 | D9: Shopee | E9: 389 | F9: https://shopee.co.th/Solakaka-SM802-%E0%B9%80%E0%B8%A1%E0%B8%B2%E0%B8%AA%E0%B9%8C%E0%B9%81%E0%B8%9A%E0%B8%9A%E0%B8%81%E0%B9%8D%E0%B8%B2%E0%B8%AB%E0%B8%99%E0%B8%94%E0%B9%80%E0%B8%AD%E0%B8%87%E0%B9%80%E0%B8%9B%E0%B8%A5%E0%B8%B5%E0%B9%88%E0%B8%A2%E0%B8%99%E0%B9%80%E0%B8%8A%E0%B8%A5%E0%B8%A5%E0%B9%8C%E0%B8%81%E0%B8%B2%E0%B8%A3%E0%B9%80%E0%B8%8A%E0%B8%B7%E0%B9%88%E0%B8%AD%E0%B8%A1%E0%B8%95%E0%B9%88%E0%B8%AD-Tri-mode-RGB-6-DPI-%E0%B8%9B%E0%B8%A3%E0%B8%B1%E0%B8%9A%E0%B8%A3%E0%B8%AD%E0%B8%87%E0%B8%A3%E0%B8%B1%E0%B8%9A%E0%B8%97%E0%B8%B5%E0%B9%88%E0%B8%81%E0%B9%8D%E0%B8%B2%E0%B8%AB%E0%B8%99%E0%B8%94%E0%B9%80%E0%B8%AD%E0%B8%87-i.1201302188.27051921848?extraParams=%7B%22display_model_id%22%3A49567302273%2C%22model_selection_logic%22%3A3%7D&sp_atk=e1282678-571e-4183-8fff-c6f2e3ce3c31&xptdk=e1282678-571e-4183-8fff-c6f2e3ce3c31 | G9: https://down-th.img.susercontent.com/file/cn-11134207-820l4-mibgmh0cw744a4.webp
A10: =INT((ROW()-2)/3)+1 -> 3 | B10: {=XLOOKUP(A10, manage_gift!A:A, manage_gift!B:B)} -> Gaming Mouse | C10: {=XLOOKUP(A10, manage_gift!A:A, manage_gift!E:E)} -> 1 | D10: Shopee | E10: 160 | F10: https://shopee.co.th/NUBWO-NM107M-Macro-Gaming-Mouse-%E0%B9%80%E0%B8%A1%E0%B8%B2%E0%B8%AA%E0%B9%8C%E0%B9%80%E0%B8%81%E0%B8%A1%E0%B8%A1%E0%B8%B4%E0%B9%88%E0%B8%87%E0%B8%A1%E0%B8%B5%E0%B8%AA%E0%B8%B2%E0%B8%A2-%E0%B9%80%E0%B8%AA%E0%B8%B5%E0%B8%A2%E0%B8%87%E0%B9%80%E0%B8%87%E0%B8%B5%E0%B8%A2%E0%B8%9A-8000DPI-%E0%B8%A1%E0%B8%B5%E0%B8%8B%E0%B8%AD%E0%B8%9F%E0%B9%81%E0%B8%A7%E0%B8%A3%E0%B9%8C%E0%B8%9B%E0%B8%A3%E0%B8%B1%E0%B8%9A%E0%B9%81%E0%B8%95%E0%B9%88%E0%B8%87-%E0%B8%9B%E0%B8%A3%E0%B8%B0%E0%B8%81%E0%B8%B1%E0%B8%99-1-%E0%B8%9B%E0%B8%B5-i.133460598.52654582846?extraParams=%7B%22display_model_id%22%3A315427871536%2C%22model_selection_logic%22%3A3%7D&sp_atk=7e1862a7-f958-4541-be20-f3266e965ce7&xptdk=7e1862a7-f958-4541-be20-f3266e965ce7 | G10: https://down-th.img.susercontent.com/file/sg-11134201-8261t-mjfbipsmcver35.webp
A11: =INT((ROW()-2)/3)+1 -> 4 | B11: {=XLOOKUP(A11, manage_gift!A:A, manage_gift!B:B)} -> Mechanical Keyboard | C11: {=XLOOKUP(A11, manage_gift!A:A, manage_gift!E:E)} -> 3 | D11: Shopee | E11: 299 | F11: https://shopee.co.th/Berlin-%E0%B8%84%E0%B8%B5%E0%B8%A2%E0%B9%8C%E0%B8%9A%E0%B8%AD%E0%B8%A3%E0%B9%8C%E0%B8%94-%E0%B9%80%E0%B8%A1%E0%B8%B2%E0%B8%AA%E0%B9%8C-RAIKU-T28-USB-%E0%B8%9B%E0%B8%B8%E0%B9%88%E0%B8%A1%E0%B9%84%E0%B8%97%E0%B8%A2-98%E0%B8%9B%E0%B8%B8%E0%B9%88%E0%B8%A1-%E0%B8%AA%E0%B9%84%E0%B8%95%E0%B8%A5%E0%B9%8C%E0%B9%80%E0%B8%81%E0%B8%A1%E0%B8%A1%E0%B8%B4%E0%B9%88%E0%B8%87-%E0%B8%84%E0%B8%B5%E0%B8%A2%E0%B9%8C%E0%B8%9A%E0%B8%AD%E0%B8%A3%E0%B9%8C%E0%B8%94%E0%B9%80%E0%B8%A5%E0%B9%88%E0%B8%99%E0%B9%80%E0%B8%81%E0%B8%A1-%E0%B9%84%E0%B8%9F%E0%B9%81%E0%B8%9A%E0%B9%87%E0%B8%84%E0%B9%84%E0%B8%A5%E0%B8%97%E0%B9%8C-Keyboard-computer-i.414803947.52653516806?extraParams=%7B%22display_model_id%22%3A400337130845%2C%22model_selection_logic%22%3A3%7D&sp_atk=85a5f6c8-939a-434b-a9e2-095fa99b26ea&xptdk=85a5f6c8-939a-434b-a9e2-095fa99b26ea | G11: https://down-th.img.susercontent.com/file/sg-11134201-81zu6-milggfl359u047.webp
A12: =INT((ROW()-2)/3)+1 -> 4 | B12: {=XLOOKUP(A12, manage_gift!A:A, manage_gift!B:B)} -> Mechanical Keyboard | C12: {=XLOOKUP(A12, manage_gift!A:A, manage_gift!E:E)} -> 3 | D12: Shopee | E12: 1350 | F12: https://shopee.co.th/%F0%9F%87%B9%F0%9F%87%AD-Keycool-Y75-%E0%B8%84%E0%B8%B5%E0%B8%A2%E0%B9%8C%E0%B8%9A%E0%B8%AD%E0%B8%A3%E0%B9%8C%E0%B8%94-Mechanical-75-%E0%B8%94%E0%B8%B5%E0%B9%84%E0%B8%8B%E0%B8%99%E0%B9%8C%E0%B8%81%E0%B8%B0%E0%B8%97%E0%B8%B1%E0%B8%94%E0%B8%A3%E0%B8%B1%E0%B8%94-%E0%B9%80%E0%B8%8A%E0%B8%B7%E0%B9%88%E0%B8%AD%E0%B8%A1%E0%B8%95%E0%B9%88%E0%B8%AD-3-%E0%B9%82%E0%B8%AB%E0%B8%A1%E0%B8%94-%E0%B9%84%E0%B8%9F-RGB-%E0%B9%80%E0%B8%AB%E0%B8%A1%E0%B8%B2%E0%B8%B0%E0%B8%81%E0%B8%B1%E0%B8%9A%E0%B9%80%E0%B8%A5%E0%B9%88%E0%B8%99%E0%B9%80%E0%B8%81%E0%B8%A1%E0%B9%81%E0%B8%A5%E0%B8%B0%E0%B8%97%E0%B8%B3%E0%B8%87%E0%B8%B2%E0%B8%99-i.1530021124.44706508961?extraParams=%7B%22display_model_id%22%3A365583870366%2C%22model_selection_logic%22%3A3%7D&sp_atk=fe2b96bc-07c6-4e66-8ebf-79b1fdb1428c&xptdk=fe2b96bc-07c6-4e66-8ebf-79b1fdb1428c | G12: https://down-th.img.susercontent.com/file/th-11134207-81ztc-ml686lfbx8g429.webp
A13: =INT((ROW()-2)/3)+1 -> 4 | B13: {=XLOOKUP(A13, manage_gift!A:A, manage_gift!B:B)} -> Mechanical Keyboard | C13: {=XLOOKUP(A13, manage_gift!A:A, manage_gift!E:E)} -> 3 | D13: Shopee | E13: 512 | F13: https://shopee.co.th/FANTECH-%E0%B8%84%E0%B8%B5%E0%B8%A2%E0%B9%8C%E0%B8%9A%E0%B8%AD%E0%B8%A3%E0%B9%8C%E0%B8%94%E0%B9%80%E0%B8%81%E0%B8%A1%E0%B8%A1%E0%B8%B4%E0%B9%88%E0%B8%87-Keyboard-Mechanical-%E0%B9%84%E0%B8%9FRGB-16-%E0%B9%82%E0%B8%AB%E0%B8%A1%E0%B8%94-Hot-Swap-5Pin-%E0%B8%AA%E0%B8%A7%E0%B8%B4%E0%B8%95%E0%B8%8A%E0%B9%8C%E0%B9%80%E0%B8%9B%E0%B8%A5%E0%B8%B5%E0%B9%88%E0%B8%A2%E0%B8%99%E0%B9%84%E0%B8%94%E0%B9%89-%E0%B8%A3%E0%B8%B8%E0%B9%88%E0%B8%99-MK613-i.136034916.42924064006?extraParams=%7B%22display_model_id%22%3A306954968223%2C%22model_selection_logic%22%3A3%7D&sp_atk=bc7ab8f7-b46c-4f08-a52b-812561f3b926&xptdk=bc7ab8f7-b46c-4f08-a52b-812561f3b926 | G13: https://down-th.img.susercontent.com/file/th-11134207-81ztj-mfxqmebvtnnwea.webp
... A601: =INT((ROW()-2)/3)+1 -> 200 | B601: {=XLOOKUP(A601, manage_gift!A:A, manage_gift!B:B)} -> Photo Album | C601: {=XLOOKUP(A601, manage_gift!A:A, manage_gift!E:E)} -> 3 | D601: Shopee | E601: 278 | F601: https://shopee.co.th/%E0%B8%AD%E0%B8%B1%E0%B8%A5%E0%B8%9A%E0%B8%B1%E0%B9%89%E0%B8%A1%E0%B8%A3%E0%B8%B9%E0%B8%9B-DIY-%E0%B8%81%E0%B8%B2%E0%B8%A7%E0%B9%83%E0%B8%99%E0%B8%95%E0%B8%B1%E0%B8%A7-%E0%B8%9B%E0%B8%81%E0%B8%9C%E0%B9%89%E0%B8%B2%E0%B9%80%E0%B8%9B%E0%B8%B4%E0%B8%94%E0%B8%AB%E0%B8%99%E0%B9%89%E0%B8%B2%E0%B8%95%E0%B9%88%E0%B8%B2%E0%B8%87-Scrapbook-Photo-Album-%E0%B8%AA%E0%B8%B3%E0%B8%AB%E0%B8%A3%E0%B8%B1%E0%B8%9A%E0%B8%84%E0%B8%A3%E0%B8%AD%E0%B8%9A%E0%B8%84%E0%B8%A3%E0%B8%B1%E0%B8%A7-%E0%B8%82%E0%B8%AD%E0%B8%87%E0%B8%82%E0%B8%A7%E0%B8%B1%E0%B8%8D-%E0%B8%84%E0%B8%A7%E0%B8%B2%E0%B8%A1%E0%B8%97%E0%B8%A3%E0%B8%87%E0%B8%88%E0%B8%B3-i.1684560059.51557746114?extraParams=%7B%22display_model_id%22%3A228261742177%2C%22model_selection_logic%22%3A3%7D&sp_atk=560e1039-e550-4072-882c-35a2a4060734&xptdk=560e1039-e550-4072-882c-35a2a4060734 | G601: https://down-th.img.susercontent.com/file/th-11134207-81ztn-mma0p3f9zj0o51.webp

Sheet tags_detail
A1: tags_id | B1: tags_name | C1: tag_type
A2: 1 | B2: tech | C2: function
A3: 2 | B3: music | C3: function
A4: 3 | B4: fitness | C4: function
A5: 4 | B5: gaming | C5: function
A6: 5 | B6: travel | C6: context
A7: 6 | B7: study | C7: context
A8: 7 | B8: work | C8: context
A9: 8 | B9: meeting | C9: context
A10: 9 | B10: streaming | C10: context
A11: 10 | B11: home | C11: context
A12: 11 | B12: yoga | C12: function
A13: 12 | B13: workout | C13: function
... A79: 78 | B79: surprise-gift | C79: emotion

Sheet gift_id,tag_id
A1: gift_id | B1: tag_id
A2: 1 | B2: 1
A3: 1 | B3: 2
A4: 1 | B4: 34
A5: 1 | B5: 17
A6: 1 | B6: 42
A7: 2 | B7: 3
A8: 2 | B8: 1
A9: 2 | B9: 42
A10: 2 | B10: 16
A11: 2 | B11: 17
A12: 3 | B12: 4
A13: 3 | B13: 1
... A1801: 200 | B1801: 71

Sheet manage_gift
A1: gift_id | B1: gift_name | C1: category_id | D1: description | E1: target_gender_id | F1: target_age_min | G1: target_age_max
A2: 1 | B2: Wireless Earbuds | C2: 1 | D2: High-quality wireless earbuds for music lovers | E2: 3 | F2: 15 | G2: 40
A3: 2 | B3: Smart Watch | C3: 1 | D3: Smart watch for fitness tracking and daily use | E3: 3 | F3: 18 | G3: 50
A4: 3 | B4: Gaming Mouse | C4: 1 | D4: High precision gaming mouse for gamers | E4: 1 | F4: 15 | G4: 35
A5: 4 | B5: Mechanical Keyboard | C5: 1 | D5: Mechanical keyboard with RGB lighting for gaming | E5: 3 | F5: 15 | G5: 40
A6: 5 | B6: Bluetooth Speaker | C6: 1 | D6: Portable speaker for music and entertainment | E6: 3 | F6: 15 | G6: 50
A7: 6 | B7: Power Bank | C7: 1 | D7: Portable power bank for charging devices | E7: 3 | F7: 15 | G7: 50
A8: 7 | B8: Portable Charger | C8: 1 | D8: Compact charger for everyday use | E8: 3 | F8: 15 | G8: 50
A9: 8 | B9: Tablet | C9: 1 | D9: Lightweight tablet for study and entertainment | E9: 3 | F9: 12 | G9: 40
A10: 9 | B10: Laptop Stand | C10: 1 | D10: Ergonomic laptop stand for work comfort | E10: 3 | F10: 18 | G10: 45
A11: 10 | B11: Monitor | C11: 1 | D11: High resolution monitor for work and gaming | E11: 3 | F11: 18 | G11: 50
A12: 11 | B12: Webcam | C12: 1 | D12: HD webcam for meetings and streaming | E12: 3 | F12: 18 | G12: 45
A13: 12 | B13: Microphone | C13: 1 | D13: Clear audio microphone for recording | E13: 3 | F13: 15 | G13: 40
... A201: 200 | B201: Photo Album | C201: 8 | D201: Photo album for storing memories | E201: 3 | F201: 15 | G201: 60

Sheet manage_category
A1: category_id | B1: category_name | C1: category_description
A2: 1 | B2: electronics | C2: Electronic devices and smart gadgets used in daily life
A3: 2 | B3: fitness | C3: Equipment and products for exercise and physical training
A4: 3 | B4: fashion | C4: Clothing and wearable items focused on personal style
A5: 4 | B5: accessories | C5: Personal accessories such as bags wallets and add-ons
A6: 5 | B6: beauty | C6: Skincare cosmetics and personal beauty products
A7: 6 | B7: kitchen | C7: Appliances and tools for cooking and food preparation
A8: 7 | B8: books | C8: Books and reading materials for knowledge and entertainment
A9: 8 | B9: home-decor | C9: Items used to decorate and improve living spaces
A10: 9 | B10: entertainment | C10: Products for fun leisure and recreation
A11: 10 | B11: furniture | C11: Large household items like tables chairs and storage
A12: 11 | B12: office | C12: Work and study related tools and office supplies
A13: 12 | B13: music | C13: Musical instruments and audio equipment
... A16: 15 | B16: sport | C16: Sports equipment and activity-related items

Sheet gender_detail
A1: gender_id | B1: gender_name
A2: 1 | B2: Male
A3: 2 | B3: Female
A4: 3 | B4: Uni

Sheet manage_vocabulary
A1: term | B1: synonyms | G1: category_id
A2: tech | B2: technology | C2: gadget | D2: device | E2: electronics | G2: 1
A3: gaming | B3: game | C3: video-game | D3: esports | E3: console | G3: 1
A4: music | B4: song | C4: audio | D4: sound | E4: instrument | G4: 12
A5: fitness | B5: workout | C5: exercise | D5: gym | E5: training | G5: 2
A6: yoga | B6: stretch | C6: meditation | D6: flexibility | G6: 2
A7: work | B7: office | C7: job | D7: career | E7: productivity | G7: 11
A8: study | B8: learning | C8: education | D8: school | E8: university | G8: 7
A9: home | B9: house | C9: living | D9: residence | E9: interior | G9: 8
A10: travel | B10: trip | C10: vacation | D10: journey | E10: tourism | G10: 14
A11: fashion | B11: style | C11: outfit | D11: clothing | E11: apparel | G11: 3
A12: beauty | B12: makeup | C12: skincare | D12: cosmetics | G12: 5
A13: coffee | B13: cafe | C13: espresso | D13: latte | E13: drink | G13: 6
A14: cooking | B14: food | C14: kitchen | D14: chef | E14: meal | F14: preparation | G14: 6
A15: healthy | B15: health | C15: wellness | D15: diet | E15: nutrition | G15: 2
A16: sport | B16: game | C16: athletics | D16: competition | G16: 15
A17: casual | B17: relaxed | C17: everyday | D17: simple | G17: 3
A18: formal | B18: suit | C18: official | D18: business | G18: 3
A19: winter | B19: cold | C19: snow | D19: warm | E19: clothing | G19: 3
A20: organization | B20: planning | C20: schedule | D20: manage | G20: 11
A21: writing | B21: notes | C21: journal | D21: diary | E21: content | G21: 7
A22: reading | B22: books | C22: novel | D22: literature | G22: 7
A23: relaxation | B23: calm | C23: rest | D23: peace | G23: 8
A24: comfort | B24: soft | C24: cozy | D24: relax | G24: 8
A25: nature | B25: plant | C25: green | D25: outdoor | G25: 14
A26: garden | B26: plants | C26: gardening | D26: outdoor | G26: 8
A27: entertainment | B27: fun | C27: leisure | D27: media | G27: 9
A28: photography | B28: camera | C28: photo | D28: video | E28: shooting | G28: 1
A29: network | B29: internet | C29: wifi | D29: connection | G29: 1
A30: office | B30: workspace | C30: desk | D30: work | G30: 11
A31: cleaning | B31: wash | C31: tidy | D31: organize | G31: 8
A32: design | B32: creative | C32: drawing | D32: art | G32: 1
A33: repair | B33: fix | C33: tools | D33: maintenance | G33: 8
A34: emergency | B34: first-aid | C34: safety | D34: urgent | G34: 13
A35: health | B35: medical | C35: care | D35: wellness | G35: 13
A36: safety | B36: protection | C36: secure | D36: safe | G36: 13
A37: hobby | B37: activity | C37: interest | D37: leisure | G37: 9
A38: memories | B38: photo | C38: album | D38: nostalgia | G38: 8
A39: streaming | B39: live | C39: video | D39: content | E39: creator | G39: 1
A40: meeting | B40: zoom | C40: call | D40: conference | G40: 11
...

Sheet manage_recommendation_rules
A1: priority | B1: name | C1: condition | D1: category
A2: 1 | B2: Tech Enthusiast | C2: interests includes tech OR gadget | D2: 1
A3: 2 | B3: Gamer | C3: interests includes gaming OR game | D3: 1
A4: 3 | B4: Music Lover | C4: interests includes music OR song | D4: 12
A5: 4 | B5: Fitness Lover | C5: interests includes fitness OR workout | D5: 2
A6: 5 | B6: Yoga Lover | C6: interests includes yoga | D6: 2
A7: 6 | B7: Office Worker | C7: interests includes work OR office | D7: 11
A8: 7 | B8: Student | C8: interests includes study OR learning | D8: 7
A9: 8 | B9: Home Lover | C9: interests includes home OR decoration | D9: 6
A10: 8 | B10: Home Lover | C10: interests includes home OR decoration | D10: 8
A11: 9 | B11: Traveler | C11: interests includes travel OR trip | D11: 4
A12: 9 | B12: Traveler | C12: interests includes travel OR trip | D12: 14
A13: 10 | B13: Fashion Lover | C13: interests includes fashion OR style | D13: 3
... A29: 25 | B29: Gift Memory Lover | C29: interests includes memory OR photo | D29: 8
